Workbook

Sheet 使い方
B1: PRスコアリングモデル
B2: 記事や番組での露出を、企業ごとの方針に沿って1件ずつ点数化し、月別・媒体別に集計するためのシートです。
B4: ■ 使い方
B5: 1. 「設定」シートの黄色セルを、自社の方針に合わせて変更します（重み、媒体ランクの基準、論調係数など）。
B6: 2. 「露出ログ」シートに掲載1件につき1行を入力します。黄色の列が入力欄で、選択肢のある列はプルダウンから選べます。
B7: 3. 灰色の列（媒体影響力点〜判定）は自動で計算されます。ここには入力しないでください。
B8: 4. 「集計」シートで、月別推移、媒体種別ごとの内訳、判定ごとの件数を確認できます。開始月だけ入力してください。
B10: ■ 点数の仕組み
B11: 各評価項目を0〜100点で採点し、「設定」の重みで加重平均したものが基礎点（0〜100）です。
B12: PRスコア ＝ 基礎点 × 論調係数。ネガティブ係数をマイナスにしておくと、リスク記事がマイナス点として集計で目立ちます。
B13: 到達規模と二次拡散は対数で配点します。部数やUUが大きい媒体だけが突出せず、専門媒体での深い露出も評価に残ります。
B15: ■ セルの色
... B21: 広告換算額のように金額へ置き換える指標ではありません。期をまたいだ比較や、施策どうしの比較に使う相対指標です。

Sheet 設定
A1: 設定（自社の方針に合わせて黄色セルを自由に変更）
A2: 1. 評価項目の重み（合計が100%でなくても自動で按分します）
A3: 評価項目 | B3: 重み | C3: 何を測るか
A4: 媒体影響力 | B4: 0.25 | C4: 媒体の格（下の媒体ランク表）。信頼性や業界での影響力を反映
A5: 到達規模 | B5: 0.15 | C5: 部数、月間UU、視聴者数など。対数で点数化するので大手媒体だけが突出しない
A6: 扱いの大きさ | B6: 0.2 | C6: 記事の主題か、一部で触れられただけか
A7: キーメッセージ伝達 | B7: 0.2 | C7: 伝えたかった要点がいくつ記事に入ったか
A8: ターゲット適合 | B8: 0.1 | C8: 読者・視聴者が自社の狙う層と合っているか
A9: ビジュアル | B9: 0.05 | C9: 写真やロゴが掲載されたか
A10: 二次拡散 | B10: 0.05 | C10: SNSでの共有数、他媒体への転載数など
A11: 合計 | B11: =SUM(B4:B10) -> 1 | C11: =IF(B11=0,"重みがすべて0です。どれか1つ以上に値を入れてください","OK（各項目は合計に対する割合で計算されます）") -> OK（各項目は合計に対する割合で計算されます）
A12: 2. 媒体ランク表（点数 0〜100）
A13: ランク | B13: 点数 | C13: 目安（自社の基準に書き換えてください）
A14: S | B14: 100 | C14: 全国紙の本紙、全国ネットのテレビ番組、業界トップの専門誌
A15: A | B15: 80 | C15: ブロック紙、主要経済誌、大手ニュースサイト
A16: B | B16: 60 | C16: 地方紙、業界専門紙、専門Webメディア
A17: C | B17: 40 | C17: フリーペーパー、ニッチなWebメディア、ブログ型メディア
A18: D | B18: 20 | C18: 配信サイトへの自動転載、まとめサイトなど
A19: 3. 扱いの大きさ（点数 0〜100）
A20: 扱い | B20: 点数 | C20: 目安
A21: 主題 | B21: 100 | C21: 見出しに社名・商品名が入り、記事全体が自社の話題
A22: 大きく紹介 | B22: 75 | C22: 複数社を扱う記事の中で、段落単位で紹介
A23: 一部で言及 | B23: 40 | C23: 1〜2文程度の言及
A24: 社名のみ | B24: 15 | C24: 社名や商品名が出るだけ
A25: 4. ターゲット適合（点数 0〜100）
A26: 適合度 | B26: 点数 | C26: 目安
A27: 高 | B27: 100 | C27: 読者層が自社の主要ターゲットとほぼ一致
A28: 中 | B28: 60 | C28: 一部が重なる
A29: 低 | B29: 20 | C29: ほとんど重ならない
A30: 5. ビジュアル（点数 0〜100）
A31: 掲載内容 | B31: 点数 | C31: 目安
A32: 写真+ロゴ | B32: 100 | C32: 商品写真や人物写真とロゴの両方
A33: 写真のみ | B33: 70
A34: ロゴのみ | B34: 50
A35: なし | B35: 0 | C35: 文字のみ
A36: 6. 論調係数（基礎点に掛ける倍率）
A37: 論調 | B37: 係数 | C37: 目安
A38: ポジティブ | B38: 1 | C38: 好意的、推奨している
A39: 中立 | B39: 0.8 | C39: 事実のみを伝えている
A40: ネガティブ | B40: -0.5 | C40: 批判的。マイナスにするとリスク記事として集計で目立ちます
...

Sheet 露出ログ
A1: 露出ログ（黄色の列を入力。灰色の列は自動計算）
A2: サンプル行（No 1〜5）は記入例です。上書きまたは行の中身を消してお使いください。
A4: No | B4: 掲載日 | C4: 媒体名 | D4: 媒体種別 | E4: 媒体ランク | F4: 記事タイトル・URL | G4: 到達規模 (部数/UU/視聴者) | H4: 扱いの大きさ | I4: 伝わった キーメッセージ数 | J4: ターゲット適合 | K4: ビジュアル | L4: 二次拡散数 (共有・転載) | M4: 論調 | N4: メモ | O4: 媒体影響力点 | P4: 到達規模点 | Q4: 扱い点 | R4: キーメッセージ点 | S4: ターゲット点 | T4: ビジュアル点 | U4: 二次拡散点 | V4: 基礎点 | W4: 論調係数 | X4: PRスコア | Y4: 判定
A5: 1 | B5: 46120 | C5: 全国紙A（サンプル） | D5: 新聞 | E5: S | F5: 新商品発表の記事 | G5: 2000000 | H5: 大きく紹介 | I5: 2 | J5: 中 | K5: 写真のみ | L5: 300 | M5: ポジティブ | O5: =IF($C5="","",IFERROR(INDEX(設定!$B$14:$B$18,MATCH($E5,設定!$A$14:$A$18,0)),0)) -> 100 | P5: =IF($C5="","",IF(N($G5)<=1,0,MIN(100,LOG10($G5)/LOG10(設定!$B$43)*100))) -> 90.014714 | Q5: =IF($C5="","",IFERROR(INDEX(設定!$B$21:$B$24,MATCH($H5,設定!$A$21:$A$24,0)),0)) -> 75 | R5: =IF($C5="","",IF(設定!$B$45<=0,0,MIN(100,N($I5)/設定!$B$45*100))) -> 66.666667 | S5: =IF($C5="","",IFERROR(INDEX(設定!$B$27:$B$29,MATCH($J5,設定!$A$27:$A$29,0)),0)) -> 60 | T5: =IF($C5="","",IFERROR(INDEX(設定!$B$32:$B$35,MATCH($K5,設定!$A$32:$A$35,0)),0)) -> 70 | U5: =IF($C5="","",IF(N($L5)<1,0,MIN(100,LOG10($L5+1)/LOG10(設定!$B$44+1)*100))) -> 61.96349 | V5: =IF($C5="","",IF(設定!$B$11=0,0,(O5*設定!$B$4+P5*設定!$B$5+Q5*設定!$B$6+R5*設定!$B$7+S5*設定!$B$8+T5*設定!$B$9+U5*設定!$B$10)/設定!$B$11)) -> 79.433715 | W5: =IF($C5="","",IFERROR(INDEX(設定!$B$38:$B$40,MATCH($M5,設定!$A$38:$A$40,0)),1)) -> 1 | X5: =IF($C5="","",ROUND(V5*W5,1)) -> 79.4 | Y5: =IF($C5="","",INDEX(設定!$B$49:$B$53,MATCH(X5,設定!$A$49:$A$53,1))) -> S
A6: 2 | B6: 46127 | C6: 業界専門紙B（サンプル） | D6: 業界専門紙誌 | E6: B | F6: 代表インタビュー | G6: 50000 | H6: 主題 | I6: 3 | J6: 高 | K6: 写真+ロゴ | L6: 120 | M6: ポジティブ | O6: =IF($C6="","",IFERROR(INDEX(設定!$B$14:$B$18,MATCH($E6,設定!$A$14:$A$18,0)),0)) -> 60 | P6: =IF($C6="","",IF(N($G6)<=1,0,MIN(100,LOG10($G6)/LOG10(設定!$B$43)*100))) -> 67.128143 | Q6: =IF($C6="","",IFERROR(INDEX(設定!$B$21:$B$24,MATCH($H6,設定!$A$21:$A$24,0)),0)) -> 100 | R6: =IF($C6="","",IF(設定!$B$45<=0,0,MIN(100,N($I6)/設定!$B$45*100))) -> 100 | S6: =IF($C6="","",IFERROR(INDEX(設定!$B$27:$B$29,MATCH($J6,設定!$A$27:$A$29,0)),0)) -> 100 | T6: =IF($C6="","",IFERROR(INDEX(設定!$B$32:$B$35,MATCH($K6,設定!$A$32:$A$35,0)),0)) -> 100 | U6: =IF($C6="","",IF(N($L6)<1,0,MIN(100,LOG10($L6+1)/LOG10(設定!$B$44+1)*100))) -> 52.069069 | V6: =IF($C6="","",IF(設定!$B$11=0,0,(O6*設定!$B$4+P6*設定!$B$5+Q6*設定!$B$6+R6*設定!$B$7+S6*設定!$B$8+T6*設定!$B$9+U6*設定!$B$10)/設定!$B$11)) -> 82.672675 | W6: =IF($C6="","",IFERROR(INDEX(設定!$B$38:$B$40,MATCH($M6,設定!$A$38:$A$40,0)),1)) -> 1 | X6: =IF($C6="","",ROUND(V6*W6,1)) -> 82.7 | Y6: =IF($C6="","",INDEX(設定!$B$49:$B$53,MATCH(X6,設定!$A$49:$A$53,1))) -> S
A7: 3 | B7: 46144 | C7: ニュースサイトC（サンプル） | D7: Webニュース | E7: A | F7: 業界動向まとめ | G7: 8000000 | H7: 一部で言及 | I7: 1 | J7: 中 | K7: なし | L7: 1500 | M7: 中立 | O7: =IF($C7="","",IFERROR(INDEX(設定!$B$14:$B$18,MATCH($E7,設定!$A$14:$A$18,0)),0)) -> 80 | P7: =IF($C7="","",IF(N($G7)<=1,0,MIN(100,LOG10($G7)/LOG10(設定!$B$43)*100))) -> 98.615571 | Q7: =IF($C7="","",IFERROR(INDEX(設定!$B$21:$B$24,MATCH($H7,設定!$A$21:$A$24,0)),0)) -> 40 | R7: =IF($C7="","",IF(設定!$B$45<=0,0,MIN(100,N($I7)/設定!$B$45*100))) -> 33.333333 | S7: =IF($C7="","",IFERROR(INDEX(設定!$B$27:$B$29,MATCH($J7,設定!$A$27:$A$29,0)),0)) -> 60 | T7: =IF($C7="","",IFERROR(INDEX(設定!$B$32:$B$35,MATCH($K7,設定!$A$32:$A$35,0)),0)) -> 0 | U7: =IF($C7="","",IF(N($L7)<1,0,MIN(100,LOG10($L7+1)/LOG10(設定!$B$44+1)*100))) -> 79.408655 | V7: =IF($C7="","",IF(設定!$B$11=0,0,(O7*設定!$B$4+P7*設定!$B$5+Q7*設定!$B$6+R7*設定!$B$7+S7*設定!$B$8+T7*設定!$B$9+U7*設定!$B$10)/設定!$B$11)) -> 59.429435 | W7: =IF($C7="","",IFERROR(INDEX(設定!$B$38:$B$40,MATCH($M7,設定!$A$38:$A$40,0)),1)) -> 0.8 | X7: =IF($C7="","",ROUND(V7*W7,1)) -> 47.5 | Y7: =IF($C7="","",INDEX(設定!$B$49:$B$53,MATCH(X7,設定!$A$49:$A$53,1))) -> B
A8: 4 | B8: 46162 | C8: 情報番組D（サンプル） | D8: テレビ | E8: S | F8: 特集コーナーで紹介 | G8: 5000000 | H8: 大きく紹介 | I8: 2 | J8: 高 | K8: 写真+ロゴ | L8: 4000 | M8: ポジティブ | O8: =IF($C8="","",IFERROR(INDEX(設定!$B$14:$B$18,MATCH($E8,設定!$A$14:$A$18,0)),0)) -> 100 | P8: =IF($C8="","",IF(N($G8)<=1,0,MIN(100,LOG10($G8)/LOG10(設定!$B$43)*100))) -> 95.699571 | Q8: =IF($C8="","",IFERROR(INDEX(設定!$B$21:$B$24,MATCH($H8,設定!$A$21:$A$24,0)),0)) -> 75 | R8: =IF($C8="","",IF(設定!$B$45<=0,0,MIN(100,N($I8)/設定!$B$45*100))) -> 66.666667 | S8: =IF($C8="","",IFERROR(INDEX(設定!$B$27:$B$29,MATCH($J8,設定!$A$27:$A$29,0)),0)) -> 100 | T8: =IF($C8="","",IFERROR(INDEX(設定!$B$32:$B$35,MATCH($K8,設定!$A$32:$A$35,0)),0)) -> 100 | U8: =IF($C8="","",IF(N($L8)<1,0,MIN(100,LOG10($L8+1)/LOG10(設定!$B$44+1)*100))) -> 90.053236 | V8: =IF($C8="","",IF(設定!$B$11=0,0,(O8*設定!$B$4+P8*設定!$B$5+Q8*設定!$B$6+R8*設定!$B$7+S8*設定!$B$8+T8*設定!$B$9+U8*設定!$B$10)/設定!$B$11)) -> 87.190931 | W8: =IF($C8="","",IFERROR(INDEX(設定!$B$38:$B$40,MATCH($M8,設定!$A$38:$A$40,0)),1)) -> 1 | X8: =IF($C8="","",ROUND(V8*W8,1)) -> 87.2 | Y8: =IF($C8="","",INDEX(設定!$B$49:$B$53,MATCH(X8,設定!$A$49:$A$53,1))) -> S
A9: 5 | B9: 46176 | C9: 経済誌E（サンプル） | D9: 雑誌 | E9: A | F9: 業界の課題を扱う記事 | G9: 150000 | H9: 一部で言及 | I9: 0 | J9: 中 | K9: ロゴのみ | L9: 50 | M9: ネガティブ | O9: =IF($C9="","",IFERROR(INDEX(設定!$B$14:$B$18,MATCH($E9,設定!$A$14:$A$18,0)),0)) -> 80 | P9: =IF($C9="","",IF(N($G9)<=1,0,MIN(100,LOG10($G9)/LOG10(設定!$B$43)*100))) -> 73.944161 | Q9: =IF($C9="","",IFERROR(INDEX(設定!$B$21:$B$24,MATCH($H9,設定!$A$21:$A$24,0)),0)) -> 40 | R9: =IF($C9="","",IF(設定!$B$45<=0,0,MIN(100,N($I9)/設定!$B$45*100))) -> 0 | S9: =IF($C9="","",IFERROR(INDEX(設定!$B$27:$B$29,MATCH($J9,設定!$A$27:$A$29,0)),0)) -> 60 | T9: =IF($C9="","",IFERROR(INDEX(設定!$B$32:$B$35,MATCH($K9,設定!$A$32:$A$35,0)),0)) -> 50 | U9: =IF($C9="","",IF(N($L9)<1,0,MIN(100,LOG10($L9+1)/LOG10(設定!$B$44+1)*100))) -> 42.688791 | V9: =IF($C9="","",IF(設定!$B$11=0,0,(O9*設定!$B$4+P9*設定!$B$5+Q9*設定!$B$6+R9*設定!$B$7+S9*設定!$B$8+T9*設定!$B$9+U9*設定!$B$10)/設定!$B$11)) -> 49.726064 | W9: =IF($C9="","",IFERROR(INDEX(設定!$B$38:$B$40,MATCH($M9,設定!$A$38:$A$40,0)),1)) -> -0.5 | X9: =IF($C9="","",ROUND(V9*W9,1)) -> -24.9 | Y9: =IF($C9="","",INDEX(設定!$B$49:$B$53,MATCH(X9,設定!$A$49:$A$53,1))) -> 要対応
A10: 6 | O10: =IF($C10="","",IFERROR(INDEX(設定!$B$14:$B$18,MATCH($E10,設定!$A$14:$A$18,0)),0)) | P10: =IF($C10="","",IF(N($G10)<=1,0,MIN(100,LOG10($G10)/LOG10(設定!$B$43)*100))) | Q10: =IF($C10="","",IFERROR(INDEX(設定!$B$21:$B$24,MATCH($H10,設定!$A$21:$A$24,0)),0)) | R10: =IF($C10="","",IF(設定!$B$45<=0,0,MIN(100,N($I10)/設定!$B$45*100))) | S10: =IF($C10="","",IFERROR(INDEX(設定!$B$27:$B$29,MATCH($J10,設定!$A$27:$A$29,0)),0)) | T10: =IF($C10="","",IFERROR(INDEX(設定!$B$32:$B$35,MATCH($K10,設定!$A$32:$A$35,0)),0)) | U10: =IF($C10="","",IF(N($L10)<1,0,MIN(100,LOG10($L10+1)/LOG10(設定!$B$44+1)*100))) | V10: =IF($C10="","",IF(設定!$B$11=0,0,(O10*設定!$B$4+P10*設定!$B$5+Q10*設定!$B$6+R10*設定!$B$7+S10*設定!$B$8+T10*設定!$B$9+U10*設定!$B$10)/設定!$B$11)) | W10: =IF($C10="","",IFERROR(INDEX(設定!$B$38:$B$40,MATCH($M10,設定!$A$38:$A$40,0)),1)) | X10: =IF($C10="","",ROUND(V10*W10,1)) | Y10: =IF($C10="","",INDEX(設定!$B$49:$B$53,MATCH(X10,設定!$A$49:$A$53,1)))
A11: 7 | O11: =IF($C11="","",IFERROR(INDEX(設定!$B$14:$B$18,MATCH($E11,設定!$A$14:$A$18,0)),0)) | P11: =IF($C11="","",IF(N($G11)<=1,0,MIN(100,LOG10($G11)/LOG10(設定!$B$43)*100))) | Q11: =IF($C11="","",IFERROR(INDEX(設定!$B$21:$B$24,MATCH($H11,設定!$A$21:$A$24,0)),0)) | R11: =IF($C11="","",IF(設定!$B$45<=0,0,MIN(100,N($I11)/設定!$B$45*100))) | S11: =IF($C11="","",IFERROR(INDEX(設定!$B$27:$B$29,MATCH($J11,設定!$A$27:$A$29,0)),0)) | T11: =IF($C11="","",IFERROR(INDEX(設定!$B$32:$B$35,MATCH($K11,設定!$A$32:$A$35,0)),0)) | U11: =IF($C11="","",IF(N($L11)<1,0,MIN(100,LOG10($L11+1)/LOG10(設定!$B$44+1)*100))) | V11: =IF($C11="","",IF(設定!$B$11=0,0,(O11*設定!$B$4+P11*設定!$B$5+Q11*設定!$B$6+R11*設定!$B$7+S11*設定!$B$8+T11*設定!$B$9+U11*設定!$B$10)/設定!$B$11)) | W11: =IF($C11="","",IFERROR(INDEX(設定!$B$38:$B$40,MATCH($M11,設定!$A$38:$A$40,0)),1)) | X11: =IF($C11="","",ROUND(V11*W11,1)) | Y11: =IF($C11="","",INDEX(設定!$B$49:$B$53,MATCH(X11,設定!$A$49:$A$53,1)))
A12: 8 | O12: =IF($C12="","",IFERROR(INDEX(設定!$B$14:$B$18,MATCH($E12,設定!$A$14:$A$18,0)),0)) | P12: =IF($C12="","",IF(N($G12)<=1,0,MIN(100,LOG10($G12)/LOG10(設定!$B$43)*100))) | Q12: =IF($C12="","",IFERROR(INDEX(設定!$B$21:$B$24,MATCH($H12,設定!$A$21:$A$24,0)),0)) | R12: =IF($C12="","",IF(設定!$B$45<=0,0,MIN(100,N($I12)/設定!$B$45*100))) | S12: =IF($C12="","",IFERROR(INDEX(設定!$B$27:$B$29,MATCH($J12,設定!$A$27:$A$29,0)),0)) | T12: =IF($C12="","",IFERROR(INDEX(設定!$B$32:$B$35,MATCH($K12,設定!$A$32:$A$35,0)),0)) | U12: =IF($C12="","",IF(N($L12)<1,0,MIN(100,LOG10($L12+1)/LOG10(設定!$B$44+1)*100))) | V12: =IF($C12="","",IF(設定!$B$11=0,0,(O12*設定!$B$4+P12*設定!$B$5+Q12*設定!$B$6+R12*設定!$B$7+S12*設定!$B$8+T12*設定!$B$9+U12*設定!$B$10)/設定!$B$11)) | W12: =IF($C12="","",IFERROR(INDEX(設定!$B$38:$B$40,MATCH($M12,設定!$A$38:$A$40,0)),1)) | X12: =IF($C12="","",ROUND(V12*W12,1)) | Y12: =IF($C12="","",INDEX(設定!$B$49:$B$53,MATCH(X12,設定!$A$49:$A$53,1)))
A13: 9 | O13: =IF($C13="","",IFERROR(INDEX(設定!$B$14:$B$18,MATCH($E13,設定!$A$14:$A$18,0)),0)) | P13: =IF($C13="","",IF(N($G13)<=1,0,MIN(100,LOG10($G13)/LOG10(設定!$B$43)*100))) | Q13: =IF($C13="","",IFERROR(INDEX(設定!$B$21:$B$24,MATCH($H13,設定!$A$21:$A$24,0)),0)) | R13: =IF($C13="","",IF(設定!$B$45<=0,0,MIN(100,N($I13)/設定!$B$45*100))) | S13: =IF($C13="","",IFERROR(INDEX(設定!$B$27:$B$29,MATCH($J13,設定!$A$27:$A$29,0)),0)) | T13: =IF($C13="","",IFERROR(INDEX(設定!$B$32:$B$35,MATCH($K13,設定!$A$32:$A$35,0)),0)) | U13: =IF($C13="","",IF(N($L13)<1,0,MIN(100,LOG10($L13+1)/LOG10(設定!$B$44+1)*100))) | V13: =IF($C13="","",IF(設定!$B$11=0,0,(O13*設定!$B$4+P13*設定!$B$5+Q13*設定!$B$6+R13*設定!$B$7+S13*設定!$B$8+T13*設定!$B$9+U13*設定!$B$10)/設定!$B$11)) | W13: =IF($C13="","",IFERROR(INDEX(設定!$B$38:$B$40,MATCH($M13,設定!$A$38:$A$40,0)),1)) | X13: =IF($C13="","",ROUND(V13*W13,1)) | Y13: =IF($C13="","",INDEX(設定!$B$49:$B$53,MATCH(X13,設定!$A$49:$A$53,1)))
A14: 10 | O14: =IF($C14="","",IFERROR(INDEX(設定!$B$14:$B$18,MATCH($E14,設定!$A$14:$A$18,0)),0)) | P14: =IF($C14="","",IF(N($G14)<=1,0,MIN(100,LOG10($G14)/LOG10(設定!$B$43)*100))) | Q14: =IF($C14="","",IFERROR(INDEX(設定!$B$21:$B$24,MATCH($H14,設定!$A$21:$A$24,0)),0)) | R14: =IF($C14="","",IF(設定!$B$45<=0,0,MIN(100,N($I14)/設定!$B$45*100))) | S14: =IF($C14="","",IFERROR(INDEX(設定!$B$27:$B$29,MATCH($J14,設定!$A$27:$A$29,0)),0)) | T14: =IF($C14="","",IFERROR(INDEX(設定!$B$32:$B$35,MATCH($K14,設定!$A$32:$A$35,0)),0)) | U14: =IF($C14="","",IF(N($L14)<1,0,MIN(100,LOG10($L14+1)/LOG10(設定!$B$44+1)*100))) | V14: =IF($C14="","",IF(設定!$B$11=0,0,(O14*設定!$B$4+P14*設定!$B$5+Q14*設定!$B$6+R14*設定!$B$7+S14*設定!$B$8+T14*設定!$B$9+U14*設定!$B$10)/設定!$B$11)) | W14: =IF($C14="","",IFERROR(INDEX(設定!$B$38:$B$40,MATCH($M14,設定!$A$38:$A$40,0)),1)) | X14: =IF($C14="","",ROUND(V14*W14,1)) | Y14: =IF($C14="","",INDEX(設定!$B$49:$B$53,MATCH(X14,設定!$A$49:$A$53,1)))
A15: 11 | O15: =IF($C15="","",IFERROR(INDEX(設定!$B$14:$B$18,MATCH($E15,設定!$A$14:$A$18,0)),0)) | P15: =IF($C15="","",IF(N($G15)<=1,0,MIN(100,LOG10($G15)/LOG10(設定!$B$43)*100))) | Q15: =IF($C15="","",IFERROR(INDEX(設定!$B$21:$B$24,MATCH($H15,設定!$A$21:$A$24,0)),0)) | R15: =IF($C15="","",IF(設定!$B$45<=0,0,MIN(100,N($I15)/設定!$B$45*100))) | S15: =IF($C15="","",IFERROR(INDEX(設定!$B$27:$B$29,MATCH($J15,設定!$A$27:$A$29,0)),0)) | T15: =IF($C15="","",IFERROR(INDEX(設定!$B$32:$B$35,MATCH($K15,設定!$A$32:$A$35,0)),0)) | U15: =IF($C15="","",IF(N($L15)<1,0,MIN(100,LOG10($L15+1)/LOG10(設定!$B$44+1)*100))) | V15: =IF($C15="","",IF(設定!$B$11=0,0,(O15*設定!$B$4+P15*設定!$B$5+Q15*設定!$B$6+R15*設定!$B$7+S15*設定!$B$8+T15*設定!$B$9+U15*設定!$B$10)/設定!$B$11)) | W15: =IF($C15="","",IFERROR(INDEX(設定!$B$38:$B$40,MATCH($M15,設定!$A$38:$A$40,0)),1)) | X15: =IF($C15="","",ROUND(V15*W15,1)) | Y15: =IF($C15="","",INDEX(設定!$B$49:$B$53,MATCH(X15,設定!$A$49:$A$53,1)))
A16: 12 | O16: =IF($C16="","",IFERROR(INDEX(設定!$B$14:$B$18,MATCH($E16,設定!$A$14:$A$18,0)),0)) | P16: =IF($C16="","",IF(N($G16)<=1,0,MIN(100,LOG10($G16)/LOG10(設定!$B$43)*100))) | Q16: =IF($C16="","",IFERROR(INDEX(設定!$B$21:$B$24,MATCH($H16,設定!$A$21:$A$24,0)),0)) | R16: =IF($C16="","",IF(設定!$B$45<=0,0,MIN(100,N($I16)/設定!$B$45*100))) | S16: =IF($C16="","",IFERROR(INDEX(設定!$B$27:$B$29,MATCH($J16,設定!$A$27:$A$29,0)),0)) | T16: =IF($C16="","",IFERROR(INDEX(設定!$B$32:$B$35,MATCH($K16,設定!$A$32:$A$35,0)),0)) | U16: =IF($C16="","",IF(N($L16)<1,0,MIN(100,LOG10($L16+1)/LOG10(設定!$B$44+1)*100))) | V16: =IF($C16="","",IF(設定!$B$11=0,0,(O16*設定!$B$4+P16*設定!$B$5+Q16*設定!$B$6+R16*設定!$B$7+S16*設定!$B$8+T16*設定!$B$9+U16*設定!$B$10)/設定!$B$11)) | W16: =IF($C16="","",IFERROR(INDEX(設定!$B$38:$B$40,MATCH($M16,設定!$A$38:$A$40,0)),1)) | X16: =IF($C16="","",ROUND(V16*W16,1)) | Y16: =IF($C16="","",INDEX(設定!$B$49:$B$53,MATCH(X16,設定!$A$49:$A$53,1)))
A17: 13 | O17: =IF($C17="","",IFERROR(INDEX(設定!$B$14:$B$18,MATCH($E17,設定!$A$14:$A$18,0)),0)) | P17: =IF($C17="","",IF(N($G17)<=1,0,MIN(100,LOG10($G17)/LOG10(設定!$B$43)*100))) | Q17: =IF($C17="","",IFERROR(INDEX(設定!$B$21:$B$24,MATCH($H17,設定!$A$21:$A$24,0)),0)) | R17: =IF($C17="","",IF(設定!$B$45<=0,0,MIN(100,N($I17)/設定!$B$45*100))) | S17: =IF($C17="","",IFERROR(INDEX(設定!$B$27:$B$29,MATCH($J17,設定!$A$27:$A$29,0)),0)) | T17: =IF($C17="","",IFERROR(INDEX(設定!$B$32:$B$35,MATCH($K17,設定!$A$32:$A$35,0)),0)) | U17: =IF($C17="","",IF(N($L17)<1,0,MIN(100,LOG10($L17+1)/LOG10(設定!$B$44+1)*100))) | V17: =IF($C17="","",IF(設定!$B$11=0,0,(O17*設定!$B$4+P17*設定!$B$5+Q17*設定!$B$6+R17*設定!$B$7+S17*設定!$B$8+T17*設定!$B$9+U17*設定!$B$10)/設定!$B$11)) | W17: =IF($C17="","",IFERROR(INDEX(設定!$B$38:$B$40,MATCH($M17,設定!$A$38:$A$40,0)),1)) | X17: =IF($C17="","",ROUND(V17*W17,1)) | Y17: =IF($C17="","",INDEX(設定!$B$49:$B$53,MATCH(X17,設定!$A$49:$A$53,1)))
A18: 14 | O18: =IF($C18="","",IFERROR(INDEX(設定!$B$14:$B$18,MATCH($E18,設定!$A$14:$A$18,0)),0)) | P18: =IF($C18="","",IF(N($G18)<=1,0,MIN(100,LOG10($G18)/LOG10(設定!$B$43)*100))) | Q18: =IF($C18="","",IFERROR(INDEX(設定!$B$21:$B$24,MATCH($H18,設定!$A$21:$A$24,0)),0)) | R18: =IF($C18="","",IF(設定!$B$45<=0,0,MIN(100,N($I18)/設定!$B$45*100))) | S18: =IF($C18="","",IFERROR(INDEX(設定!$B$27:$B$29,MATCH($J18,設定!$A$27:$A$29,0)),0)) | T18: =IF($C18="","",IFERROR(INDEX(設定!$B$32:$B$35,MATCH($K18,設定!$A$32:$A$35,0)),0)) | U18: =IF($C18="","",IF(N($L18)<1,0,MIN(100,LOG10($L18+1)/LOG10(設定!$B$44+1)*100))) | V18: =IF($C18="","",IF(設定!$B$11=0,0,(O18*設定!$B$4+P18*設定!$B$5+Q18*設定!$B$6+R18*設定!$B$7+S18*設定!$B$8+T18*設定!$B$9+U18*設定!$B$10)/設定!$B$11)) | W18: =IF($C18="","",IFERROR(INDEX(設定!$B$38:$B$40,MATCH($M18,設定!$A$38:$A$40,0)),1)) | X18: =IF($C18="","",ROUND(V18*W18,1)) | Y18: =IF($C18="","",INDEX(設定!$B$49:$B$53,MATCH(X18,設定!$A$49:$A$53,1)))
A19: 15 | O19: =IF($C19="","",IFERROR(INDEX(設定!$B$14:$B$18,MATCH($E19,設定!$A$14:$A$18,0)),0)) | P19: =IF($C19="","",IF(N($G19)<=1,0,MIN(100,LOG10($G19)/LOG10(設定!$B$43)*100))) | Q19: =IF($C19="","",IFERROR(INDEX(設定!$B$21:$B$24,MATCH($H19,設定!$A$21:$A$24,0)),0)) | R19: =IF($C19="","",IF(設定!$B$45<=0,0,MIN(100,N($I19)/設定!$B$45*100))) | S19: =IF($C19="","",IFERROR(INDEX(設定!$B$27:$B$29,MATCH($J19,設定!$A$27:$A$29,0)),0)) | T19: =IF($C19="","",IFERROR(INDEX(設定!$B$32:$B$35,MATCH($K19,設定!$A$32:$A$35,0)),0)) | U19: =IF($C19="","",IF(N($L19)<1,0,MIN(100,LOG10($L19+1)/LOG10(設定!$B$44+1)*100))) | V19: =IF($C19="","",IF(設定!$B$11=0,0,(O19*設定!$B$4+P19*設定!$B$5+Q19*設定!$B$6+R19*設定!$B$7+S19*設定!$B$8+T19*設定!$B$9+U19*設定!$B$10)/設定!$B$11)) | W19: =IF($C19="","",IFERROR(INDEX(設定!$B$38:$B$40,MATCH($M19,設定!$A$38:$A$40,0)),1)) | X19: =IF($C19="","",ROUND(V19*W19,1)) | Y19: =IF($C19="","",INDEX(設定!$B$49:$B$53,MATCH(X19,設定!$A$49:$A$53,1)))
A20: 16 | O20: =IF($C20="","",IFERROR(INDEX(設定!$B$14:$B$18,MATCH($E20,設定!$A$14:$A$18,0)),0)) | P20: =IF($C20="","",IF(N($G20)<=1,0,MIN(100,LOG10($G20)/LOG10(設定!$B$43)*100))) | Q20: =IF($C20="","",IFERROR(INDEX(設定!$B$21:$B$24,MATCH($H20,設定!$A$21:$A$24,0)),0)) | R20: =IF($C20="","",IF(設定!$B$45<=0,0,MIN(100,N($I20)/設定!$B$45*100))) | S20: =IF($C20="","",IFERROR(INDEX(設定!$B$27:$B$29,MATCH($J20,設定!$A$27:$A$29,0)),0)) | T20: =IF($C20="","",IFERROR(INDEX(設定!$B$32:$B$35,MATCH($K20,設定!$A$32:$A$35,0)),0)) | U20: =IF($C20="","",IF(N($L20)<1,0,MIN(100,LOG10($L20+1)/LOG10(設定!$B$44+1)*100))) | V20: =IF($C20="","",IF(設定!$B$11=0,0,(O20*設定!$B$4+P20*設定!$B$5+Q20*設定!$B$6+R20*設定!$B$7+S20*設定!$B$8+T20*設定!$B$9+U20*設定!$B$10)/設定!$B$11)) | W20: =IF($C20="","",IFERROR(INDEX(設定!$B$38:$B$40,MATCH($M20,設定!$A$38:$A$40,0)),1)) | X20: =IF($C20="","",ROUND(V20*W20,1)) | Y20: =IF($C20="","",INDEX(設定!$B$49:$B$53,MATCH(X20,設定!$A$49:$A$53,1)))
A21: 17 | O21: =IF($C21="","",IFERROR(INDEX(設定!$B$14:$B$18,MATCH($E21,設定!$A$14:$A$18,0)),0)) | P21: =IF($C21="","",IF(N($G21)<=1,0,MIN(100,LOG10($G21)/LOG10(設定!$B$43)*100))) | Q21: =IF($C21="","",IFERROR(INDEX(設定!$B$21:$B$24,MATCH($H21,設定!$A$21:$A$24,0)),0)) | R21: =IF($C21="","",IF(設定!$B$45<=0,0,MIN(100,N($I21)/設定!$B$45*100))) | S21: =IF($C21="","",IFERROR(INDEX(設定!$B$27:$B$29,MATCH($J21,設定!$A$27:$A$29,0)),0)) | T21: =IF($C21="","",IFERROR(INDEX(設定!$B$32:$B$35,MATCH($K21,設定!$A$32:$A$35,0)),0)) | U21: =IF($C21="","",IF(N($L21)<1,0,MIN(100,LOG10($L21+1)/LOG10(設定!$B$44+1)*100))) | V21: =IF($C21="","",IF(設定!$B$11=0,0,(O21*設定!$B$4+P21*設定!$B$5+Q21*設定!$B$6+R21*設定!$B$7+S21*設定!$B$8+T21*設定!$B$9+U21*設定!$B$10)/設定!$B$11)) | W21: =IF($C21="","",IFERROR(INDEX(設定!$B$38:$B$40,MATCH($M21,設定!$A$38:$A$40,0)),1)) | X21: =IF($C21="","",ROUND(V21*W21,1)) | Y21: =IF($C21="","",INDEX(設定!$B$49:$B$53,MATCH(X21,設定!$A$49:$A$53,1)))
... A304: 300 | O304: =IF($C304="","",IFERROR(INDEX(設定!$B$14:$B$18,MATCH($E304,設定!$A$14:$A$18,0)),0)) | P304: =IF($C304="","",IF(N($G304)<=1,0,MIN(100,LOG10($G304)/LOG10(設定!$B$43)*100))) | Q304: =IF($C304="","",IFERROR(INDEX(設定!$B$21:$B$24,MATCH($H304,設定!$A$21:$A$24,0)),0)) | R304: =IF($C304="","",IF(設定!$B$45<=0,0,MIN(100,N($I304)/設定!$B$45*100))) | S304: =IF($C304="","",IFERROR(INDEX(設定!$B$27:$B$29,MATCH($J304,設定!$A$27:$A$29,0)),0)) | T304: =IF($C304="","",IFERROR(INDEX(設定!$B$32:$B$35,MATCH($K304,設定!$A$32:$A$35,0)),0)) | U304: =IF($C304="","",IF(N($L304)<1,0,MIN(100,LOG10($L304+1)/LOG10(設定!$B$44+1)*100))) | V304: =IF($C304="","",IF(設定!$B$11=0,0,(O304*設定!$B$4+P304*設定!$B$5+Q304*設定!$B$6+R304*設定!$B$7+S304*設定!$B$8+T304*設定!$B$9+U304*設定!$B$10)/設定!$B$11)) | W304: =IF($C304="","",IFERROR(INDEX(設定!$B$38:$B$40,MATCH($M304,設定!$A$38:$A$40,0)),1)) | X304: =IF($C304="","",ROUND(V304*W304,1)) | Y304: =IF($C304="","",INDEX(設定!$B$49:$B$53,MATCH(X304,設定!$A$49:$A$53,1)))

Sheet 集計
A1: 集計（すべて自動計算）
A3: 全体サマリー
A4: 掲載件数 | B4: =COUNTIF(露出ログ!$C$5:$C$304,"?*") -> 5
A5: PRスコア合計 | B5: =SUM(露出ログ!$X$5:$X$304) -> 271.9
A6: 1件あたり平均 | B6: =IF(B4=0,0,B5/B4) -> 54.38
A7: ネガティブ件数 | B7: =COUNTIF(露出ログ!$Y$5:$Y$304,"要対応") -> 1
A8: ポジティブ率 | B8: =IF(B4=0,0,COUNTIFS(露出ログ!$C$5:$C$304,"?*",露出ログ!$M$5:$M$304,設定!$A$38)/B4) -> 0.6 | C8: ポジティブ率：論調が設定シート6.の1行目（初期値ポジティブ）の記事の割合
A11: 月別推移 | C11: 開始月 | D11: 46113 | E11: ← 年度の最初の月を入力
A12: 月 | B12: 件数 | C12: スコア合計 | D12: 平均スコア | E12: ネガティブ件数
A13: =EDATE($D$11,0) -> 46113 | B13: =COUNTIFS(露出ログ!$B$5:$B$304,">="&$A13,露出ログ!$B$5:$B$304,"<"&EDATE($A13,1),露出ログ!$C$5:$C$304,"?*") -> 2 | C13: =SUMIFS(露出ログ!$X$5:$X$304,露出ログ!$B$5:$B$304,">="&$A13,露出ログ!$B$5:$B$304,"<"&EDATE($A13,1)) -> 162.1 | D13: =IF(B13=0,0,C13/B13) -> 81.05 | E13: =COUNTIFS(露出ログ!$B$5:$B$304,">="&$A13,露出ログ!$B$5:$B$304,"<"&EDATE($A13,1),露出ログ!$Y$5:$Y$304,"要対応") -> 0
A14: =EDATE($D$11,1) -> 46143 | B14: =COUNTIFS(露出ログ!$B$5:$B$304,">="&$A14,露出ログ!$B$5:$B$304,"<"&EDATE($A14,1),露出ログ!$C$5:$C$304,"?*") -> 2 | C14: =SUMIFS(露出ログ!$X$5:$X$304,露出ログ!$B$5:$B$304,">="&$A14,露出ログ!$B$5:$B$304,"<"&EDATE($A14,1)) -> 134.7 | D14: =IF(B14=0,0,C14/B14) -> 67.35 | E14: =COUNTIFS(露出ログ!$B$5:$B$304,">="&$A14,露出ログ!$B$5:$B$304,"<"&EDATE($A14,1),露出ログ!$Y$5:$Y$304,"要対応") -> 0
A15: =EDATE($D$11,2) -> 46174 | B15: =COUNTIFS(露出ログ!$B$5:$B$304,">="&$A15,露出ログ!$B$5:$B$304,"<"&EDATE($A15,1),露出ログ!$C$5:$C$304,"?*") -> 1 | C15: =SUMIFS(露出ログ!$X$5:$X$304,露出ログ!$B$5:$B$304,">="&$A15,露出ログ!$B$5:$B$304,"<"&EDATE($A15,1)) -> -24.9 | D15: =IF(B15=0,0,C15/B15) -> -24.9 | E15: =COUNTIFS(露出ログ!$B$5:$B$304,">="&$A15,露出ログ!$B$5:$B$304,"<"&EDATE($A15,1),露出ログ!$Y$5:$Y$304,"要対応") -> 1
A16: =EDATE($D$11,3) -> 46204 | B16: =COUNTIFS(露出ログ!$B$5:$B$304,">="&$A16,露出ログ!$B$5:$B$304,"<"&EDATE($A16,1),露出ログ!$C$5:$C$304,"?*") -> 0 | C16: =SUMIFS(露出ログ!$X$5:$X$304,露出ログ!$B$5:$B$304,">="&$A16,露出ログ!$B$5:$B$304,"<"&EDATE($A16,1)) -> 0 | D16: =IF(B16=0,0,C16/B16) -> 0 | E16: =COUNTIFS(露出ログ!$B$5:$B$304,">="&$A16,露出ログ!$B$5:$B$304,"<"&EDATE($A16,1),露出ログ!$Y$5:$Y$304,"要対応") -> 0
A17: =EDATE($D$11,4) -> 46235 | B17: =COUNTIFS(露出ログ!$B$5:$B$304,">="&$A17,露出ログ!$B$5:$B$304,"<"&EDATE($A17,1),露出ログ!$C$5:$C$304,"?*") -> 0 | C17: =SUMIFS(露出ログ!$X$5:$X$304,露出ログ!$B$5:$B$304,">="&$A17,露出ログ!$B$5:$B$304,"<"&EDATE($A17,1)) -> 0 | D17: =IF(B17=0,0,C17/B17) -> 0 | E17: =COUNTIFS(露出ログ!$B$5:$B$304,">="&$A17,露出ログ!$B$5:$B$304,"<"&EDATE($A17,1),露出ログ!$Y$5:$Y$304,"要対応") -> 0
A18: =EDATE($D$11,5) -> 46266 | B18: =COUNTIFS(露出ログ!$B$5:$B$304,">="&$A18,露出ログ!$B$5:$B$304,"<"&EDATE($A18,1),露出ログ!$C$5:$C$304,"?*") -> 0 | C18: =SUMIFS(露出ログ!$X$5:$X$304,露出ログ!$B$5:$B$304,">="&$A18,露出ログ!$B$5:$B$304,"<"&EDATE($A18,1)) -> 0 | D18: =IF(B18=0,0,C18/B18) -> 0 | E18: =COUNTIFS(露出ログ!$B$5:$B$304,">="&$A18,露出ログ!$B$5:$B$304,"<"&EDATE($A18,1),露出ログ!$Y$5:$Y$304,"要対応") -> 0
A19: =EDATE($D$11,6) -> 46296 | B19: =COUNTIFS(露出ログ!$B$5:$B$304,">="&$A19,露出ログ!$B$5:$B$304,"<"&EDATE($A19,1),露出ログ!$C$5:$C$304,"?*") -> 0 | C19: =SUMIFS(露出ログ!$X$5:$X$304,露出ログ!$B$5:$B$304,">="&$A19,露出ログ!$B$5:$B$304,"<"&EDATE($A19,1)) -> 0 | D19: =IF(B19=0,0,C19/B19) -> 0 | E19: =COUNTIFS(露出ログ!$B$5:$B$304,">="&$A19,露出ログ!$B$5:$B$304,"<"&EDATE($A19,1),露出ログ!$Y$5:$Y$304,"要対応") -> 0
A20: =EDATE($D$11,7) -> 46327 | B20: =COUNTIFS(露出ログ!$B$5:$B$304,">="&$A20,露出ログ!$B$5:$B$304,"<"&EDATE($A20,1),露出ログ!$C$5:$C$304,"?*") -> 0 | C20: =SUMIFS(露出ログ!$X$5:$X$304,露出ログ!$B$5:$B$304,">="&$A20,露出ログ!$B$5:$B$304,"<"&EDATE($A20,1)) -> 0 | D20: =IF(B20=0,0,C20/B20) -> 0 | E20: =COUNTIFS(露出ログ!$B$5:$B$304,">="&$A20,露出ログ!$B$5:$B$304,"<"&EDATE($A20,1),露出ログ!$Y$5:$Y$304,"要対応") -> 0
A21: =EDATE($D$11,8) -> 46357 | B21: =COUNTIFS(露出ログ!$B$5:$B$304,">="&$A21,露出ログ!$B$5:$B$304,"<"&EDATE($A21,1),露出ログ!$C$5:$C$304,"?*") -> 0 | C21: =SUMIFS(露出ログ!$X$5:$X$304,露出ログ!$B$5:$B$304,">="&$A21,露出ログ!$B$5:$B$304,"<"&EDATE($A21,1)) -> 0 | D21: =IF(B21=0,0,C21/B21) -> 0 | E21: =COUNTIFS(露出ログ!$B$5:$B$304,">="&$A21,露出ログ!$B$5:$B$304,"<"&EDATE($A21,1),露出ログ!$Y$5:$Y$304,"要対応") -> 0
A22: =EDATE($D$11,9) -> 46388 | B22: =COUNTIFS(露出ログ!$B$5:$B$304,">="&$A22,露出ログ!$B$5:$B$304,"<"&EDATE($A22,1),露出ログ!$C$5:$C$304,"?*") -> 0 | C22: =SUMIFS(露出ログ!$X$5:$X$304,露出ログ!$B$5:$B$304,">="&$A22,露出ログ!$B$5:$B$304,"<"&EDATE($A22,1)) -> 0 | D22: =IF(B22=0,0,C22/B22) -> 0 | E22: =COUNTIFS(露出ログ!$B$5:$B$304,">="&$A22,露出ログ!$B$5:$B$304,"<"&EDATE($A22,1),露出ログ!$Y$5:$Y$304,"要対応") -> 0
A23: =EDATE($D$11,10) -> 46419 | B23: =COUNTIFS(露出ログ!$B$5:$B$304,">="&$A23,露出ログ!$B$5:$B$304,"<"&EDATE($A23,1),露出ログ!$C$5:$C$304,"?*") -> 0 | C23: =SUMIFS(露出ログ!$X$5:$X$304,露出ログ!$B$5:$B$304,">="&$A23,露出ログ!$B$5:$B$304,"<"&EDATE($A23,1)) -> 0 | D23: =IF(B23=0,0,C23/B23) -> 0 | E23: =COUNTIFS(露出ログ!$B$5:$B$304,">="&$A23,露出ログ!$B$5:$B$304,"<"&EDATE($A23,1),露出ログ!$Y$5:$Y$304,"要対応") -> 0
A24: =EDATE($D$11,11) -> 46447 | B24: =COUNTIFS(露出ログ!$B$5:$B$304,">="&$A24,露出ログ!$B$5:$B$304,"<"&EDATE($A24,1),露出ログ!$C$5:$C$304,"?*") -> 0 | C24: =SUMIFS(露出ログ!$X$5:$X$304,露出ログ!$B$5:$B$304,">="&$A24,露出ログ!$B$5:$B$304,"<"&EDATE($A24,1)) -> 0 | D24: =IF(B24=0,0,C24/B24) -> 0 | E24: =COUNTIFS(露出ログ!$B$5:$B$304,">="&$A24,露出ログ!$B$5:$B$304,"<"&EDATE($A24,1),露出ログ!$Y$5:$Y$304,"要対応") -> 0
A25: 合計 | B25: =SUM(B13:B24) -> 5 | C25: =SUM(C13:C24) -> 271.9 | D25: =IF(B25=0,0,C25/B25) -> 54.38 | E25: =SUM(E13:E24) -> 1
A28: 媒体種別ごと
A29: 媒体種別 | B29: 件数 | C29: スコア合計 | D29: 平均スコア | E29: 構成比
A30: =設定!A57 -> 新聞 | B30: =IF($A30="",0,COUNTIFS(露出ログ!$D$5:$D$304,$A30,露出ログ!$C$5:$C$304,"?*")) -> 1 | C30: =IF($A30="",0,SUMIFS(露出ログ!$X$5:$X$304,露出ログ!$D$5:$D$304,$A30)) -> 79.4 | D30: =IF(B30=0,0,C30/B30) -> 79.4 | E30: =IF($B$5=0,0,C30/$B$5) -> 0.29201912
A31: =設定!A58 -> テレビ | B31: =IF($A31="",0,COUNTIFS(露出ログ!$D$5:$D$304,$A31,露出ログ!$C$5:$C$304,"?*")) -> 1 | C31: =IF($A31="",0,SUMIFS(露出ログ!$X$5:$X$304,露出ログ!$D$5:$D$304,$A31)) -> 87.2 | D31: =IF(B31=0,0,C31/B31) -> 87.2 | E31: =IF($B$5=0,0,C31/$B$5) -> 0.32070614
A32: =設定!A59 -> ラジオ | B32: =IF($A32="",0,COUNTIFS(露出ログ!$D$5:$D$304,$A32,露出ログ!$C$5:$C$304,"?*")) -> 0 | C32: =IF($A32="",0,SUMIFS(露出ログ!$X$5:$X$304,露出ログ!$D$5:$D$304,$A32)) -> 0 | D32: =IF(B32=0,0,C32/B32) -> 0 | E32: =IF($B$5=0,0,C32/$B$5) -> 0
A33: =設定!A60 -> 雑誌 | B33: =IF($A33="",0,COUNTIFS(露出ログ!$D$5:$D$304,$A33,露出ログ!$C$5:$C$304,"?*")) -> 1 | C33: =IF($A33="",0,SUMIFS(露出ログ!$X$5:$X$304,露出ログ!$D$5:$D$304,$A33)) -> -24.9 | D33: =IF(B33=0,0,C33/B33) -> -24.9 | E33: =IF($B$5=0,0,C33/$B$5) -> -0.091577786
A34: =設定!A61 -> Webニュース | B34: =IF($A34="",0,COUNTIFS(露出ログ!$D$5:$D$304,$A34,露出ログ!$C$5:$C$304,"?*")) -> 1 | C34: =IF($A34="",0,SUMIFS(露出ログ!$X$5:$X$304,露出ログ!$D$5:$D$304,$A34)) -> 47.5 | D34: =IF(B34=0,0,C34/B34) -> 47.5 | E34: =IF($B$5=0,0,C34/$B$5) -> 0.17469658
A35: =設定!A62 -> 業界専門紙誌 | B35: =IF($A35="",0,COUNTIFS(露出ログ!$D$5:$D$304,$A35,露出ログ!$C$5:$C$304,"?*")) -> 1 | C35: =IF($A35="",0,SUMIFS(露出ログ!$X$5:$X$304,露出ログ!$D$5:$D$304,$A35)) -> 82.7 | D35: =IF(B35=0,0,C35/B35) -> 82.7 | E35: =IF($B$5=0,0,C35/$B$5) -> 0.30415594
A36: =設定!A63 -> SNS・動画 | B36: =IF($A36="",0,COUNTIFS(露出ログ!$D$5:$D$304,$A36,露出ログ!$C$5:$C$304,"?*")) -> 0 | C36: =IF($A36="",0,SUMIFS(露出ログ!$X$5:$X$304,露出ログ!$D$5:$D$304,$A36)) -> 0 | D36: =IF(B36=0,0,C36/B36) -> 0 | E36: =IF($B$5=0,0,C36/$B$5) -> 0
A37: =設定!A64 -> その他 | B37: =IF($A37="",0,COUNTIFS(露出ログ!$D$5:$D$304,$A37,露出ログ!$C$5:$C$304,"?*")) -> 0 | C37: =IF($A37="",0,SUMIFS(露出ログ!$X$5:$X$304,露出ログ!$D$5:$D$304,$A37)) -> 0 | D37: =IF(B37=0,0,C37/B37) -> 0 | E37: =IF($B$5=0,0,C37/$B$5) -> 0
A40: 判定ごとの件数
A41: 判定 | B41: 件数
A42: =設定!B53 -> S | B42: =COUNTIF(露出ログ!$Y$5:$Y$304,A42) -> 3
A43: =設定!B52 -> A | B43: =COUNTIF(露出ログ!$Y$5:$Y$304,A43) -> 0
A44: =設定!B51 -> B | B44: =COUNTIF(露出ログ!$Y$5:$Y$304,A44) -> 1
A45: =設定!B50 -> C | B45: =COUNTIF(露出ログ!$Y$5:$Y$304,A45) -> 0
A46: =設定!B49 -> 要対応 | B46: =COUNTIF(露出ログ!$Y$5:$Y$304,A46) -> 1
